Workbook

Sheet README
A1: AuthorsLab Financial Model — Skeleton V0.1
A2: AL-PC-FM-001 · 2026-07-28 · AL Pricing Chat · Currency: GBP · Horizon: 36 months monthly from launch (Assumptions!B5)
A4: PURPOSE
A5: Skeleton for the one-time-$299 → subscription transition model feeding the September 2026 investment push.
A6: Structure: Assumptions → lmo_ledger (COGS instrument) → Funnel → Revenue → COGS → P&L → Metrics.
A7: All placeholder values are deliberately conservative and exist to be stress-tested, not believed.
A9: EVIDENCE CLASSES — every input on the Assumptions tab carries one (column D), per pricing-chat protocol:
A10: SOURCE — verified external research or direct site fetch. Reference in column E.
A11: INSTRUMENT — to be read from lmo_ledger (live 2026-07-27). Placeholders marked PENDING until SysAdmin views arrive.
A12: ASSUMPTION — modelling choice awaiting stress-test (Van Westendorp, cohort data, or Paul's decision).
A14: COLOUR LEGEND
A15: Blue text = hardcoded input you can edit. Black = formula (do not overwrite). Green = pull from another tab.
... A28: 4. Funnel pass repricing question (verified one-time band $59.99–$147 vs current $299 — AL-PC-PBR-001 §3.4).

Sheet Assumptions
A1: Assumptions — every line carries an evidence class
A2: Blue = editable input. Yellow = key lever / pending instrument reading.
A3: Item | B3: Value | C3: Unit | D3: Basis | E3: Source / note
A4: GENERAL
A5: Model start (subscription launch) | B5: =DATE(2026,10,1) -> 46296 | C5: month | D5: ASSUMPTION | E5: Launch after Sept 2026 push + Jacky Klein demo. Edit via DATE().
A6: FX rate | B6: 1.26 | C6: USD per £1 | D6: ASSUMPTION | E6: Static convention carried from AL-SIS-PRR-001 (£19 ≈ $24). Refresh before deck.
A8: WRITER TIER PRICING — stress-test frame, NOT decided (options paper pending)
A9: Starter — monthly billed | B9: 10 | C9: £/mo | D9: SOURCE | E9: AL-SIS-PRR-001 §6 range £9–12; bracket annual-equiv floor ~£8 (AL-PC-PBR-001 §1).
A10: Starter — annual effective | B10: 7 | C10: £/mo | D10: ASSUMPTION | E10: 30% annual discount; bracket norm is 17–67% (AL-PC-PBR-001 §3.2).
A11: Author (flagship) — monthly billed | B11: 19 | C11: £/mo | D11: SOURCE | E11: Paul's £19 validated in-range (AL-SIS-PRR-001 §6); DIY stack comparison ≈ $34/mo (AL-PC-PBR-001 §4).
A12: Author — annual effective | B12: 13 | C12: £/mo | D12: ASSUMPTION | E12: ~32% annual discount → sits between Grammarly ($12) and Sudowrite Pro annual ($22).
A13: Pro — monthly billed | B13: 39 | C13: £/mo | D13: SOURCE | E13: AL-SIS-PRR-001 §6 range £39–49.
A14: Pro — annual effective | B14: 27 | C14: £/mo | D14: ASSUMPTION | E14: ~31% annual discount.
A15: Share of subscribers on annual billing | B15: 0.4 | C15: % | D15: ASSUMPTION | E15: Bracket pushes annual hard (PWA 67% discount). Test on cohort.
A16: Starter — blended £/mo | B16: =B15*B10+(1-B15)*B9 -> 8.8 | C16: £/mo | D16: formula | E16: Annual share × annual effective + monthly share × monthly.
A17: Author — blended £/mo | B17: =B15*B12+(1-B15)*B11 -> 16.6 | C17: £/mo | D17: formula
A18: Pro — blended £/mo | B18: =B15*B14+(1-B15)*B13 -> 34.2 | C18: £/mo | D18: formula
A19: One-time per-book pass | B19: 119 | C19: £ | D19: ASSUMPTION | E19: ≈$150. Verified one-time band $59.99–$147 (AL-PC-PBR-001 §3.4); current $299 is 2× Atticus — repricing question open.
A20: Imprint SKU | B20: 500 | C20: £/mo | D20: SOURCE | E20: Priced against Consonance £600/mo floor (8 × £75 seats); range £250–750 (AL-SIS-PRR-001 §6).
A21: Grandfather price (beta cohort) | B21: 9.5 | C21: £/mo | D21: ASSUMPTION | E21: 50% of Author monthly. Deliberate grandfathering per Cursor cautionary tale (AL-SIS-PRR-001 §4). Paul to decide.
A22: Grandfathered beta authors | B22: 11 | C22: authors | D22: SOURCE | E22: Live base 2026-07-28: 11 authors, 8 manuscripts, 272 chapters (founding brief §2.6).
A24: FUNNEL — all to stress-test; no historical subscription funnel exists yet
A25: Site visitors, month 1 | B25: 2000 | C25: /mo | D25: ASSUMPTION | E25: Placeholder. Wire to analytics when available.
A26: Visitor growth | B26: 0.1 | C26: %/mo | D26: ASSUMPTION | E26: Compounding. Marketing-driven; see Opex.
A27: Visitor → free full-manuscript analysis | B27: 0.05 | C27: % | D27: ASSUMPTION | E27: Free analysis stays the top-of-funnel (site fetch 2026-07-28).
A28: Free analysis → paid subscription | B28: 0.08 | C28: % | D28: ASSUMPTION | E28: Key lever. Test with Van Westendorp + beta behaviour.
A29: New-subscriber mix — Starter | B29: 0.4 | C29: % | D29: ASSUMPTION | E29: Bimodal market: 44% of indies earn ≤$100/mo from books (AL-SIS-PRR-001 §1).
A30: New-subscriber mix — Author | B30: 0.45 | C30: % | D30: ASSUMPTION | E30: Flagship.
A31: New-subscriber mix — Pro | B31: 0.15 | C31: % | D31: ASSUMPTION
A32: One-time passes per free analysis | B32: 0.02 | C32: % | D32: ASSUMPTION | E32: Pass retained as funnel product (AL-SIS-PRR-001 §6).
A34: CHURN — monthly; no cohort data yet, all ASSUMPTION
A35: Starter churn | B35: 0.08 | C35: %/mo | D35: ASSUMPTION | E35: Hobbyist tier churns hardest (price-sensitive bottom of bimodal market).
A36: Author churn | B36: 0.05 | C36: %/mo | D36: ASSUMPTION
A37: Pro churn | B37: 0.03 | C37: %/mo | D37: ASSUMPTION
A38: Imprint churn | B38: 0.01 | C38: %/mo | D38: ASSUMPTION | E38: B2B annual contracts in practice; modelled monthly.
A39: Grandfathered cohort churn | B39: 0.03 | C39: %/mo | D39: ASSUMPTION | E39: Committed beta users; grandfathering exists to keep this low.
A41: COGS — the instrument section: lines wired to lmo_ledger readings
A42: Cost per deep analysis pass (all stations) | B42: =lmo_ledger!B13 -> 3 | C42: £/pass | D42: INSTRUMENT | E42: PENDING — pulls lmo_ledger tab total. Replace station placeholders with measured aggregates.
A43: Non-pass AI cost per active author-month | B43: 1.5 | C43: £/author-mo | D43: INSTRUMENT | E43: PENDING — chat + incidental calls. SysAdmin view requested (README).
A44: Deep passes included — Starter | B44: 1 | C44: /mo | D44: ASSUMPTION | E44: Benchmark: PWA Chapter Critique 1/day at Premium (AL-PC-PBR-001 §3.3). Size from measured cost.
...

Sheet lmo_ledger
A1: lmo_ledger — COGS instrument tab
A2: The ledger (live 2026-07-27) records model, tokens and cost per AI call per station per author.
A3: Replace the yellow placeholders below with measured aggregates as the Craft Call rolls out. Ledger costs are USD — divide by Assumptions!B6.
A5: Station (full-manuscript deep pass) | B5: Cost per pass (£) | C5: Basis | D5: Note
A6: Developmental (Alex) | B6: 0.9 | C6: INSTRUMENT — PENDING | D6: First station live in Craft Call — first real readings land here
A7: Line (Jordan) | B7: 0.7 | C7: INSTRUMENT — PENDING
A8: Copy (Sam) | B8: 0.6 | C8: INSTRUMENT — PENDING
A9: Publishing prep | B9: 0.4 | C9: INSTRUMENT — PENDING
A10: Marketing | B10: 0.4 | C10: INSTRUMENT — PENDING
A13: TOTAL cost per deep pass | B13: =SUM(B6:B10) -> 3 | D13: Consumed by Assumptions!B42 → COGS tab.
A15: Views requested from SysAdmin (route via AL – System Admin):
A16: 1. avg cost per station per full-manuscript pass (per manuscript, trailing 30d)
A17: 2. avg non-pass AI cost per active author-month (chat + incidental calls)
A18: 3. tokens + cost by model, monthly — for margin sensitivity to model pricing changes

Sheet Funnel
B1: Funnel & subscribers
B3: Month | C3: 1 | D3: 2 | E3: 3 | F3: 4 | G3: 5 | H3: 6 | I3: 7 | J3: 8 | K3: 9 | L3: 10 | M3: 11 | N3: 12 | O3: 13 | P3: 14 | Q3: 15 | R3: 16 | S3: 17 | T3: 18 | U3: 19 | V3: 20 | W3: 21 | X3: 22 | Y3: 23 | Z3: 24 | AA3: 25 | AB3: 26 | AC3: 27 | AD3: 28 | AE3: 29 | AF3: 30 | AG3: 31 | AH3: 32 | AI3: 33 | AJ3: 34 | AK3: 35 | AL3: 36
B4: Period | C4: =Assumptions!$B$5 -> 46296 | D4: =EDATE(C4,1) -> 46327 | E4: =EDATE(D4,1) -> 46357 | F4: =EDATE(E4,1) -> 46388 | G4: =EDATE(F4,1) -> 46419 | H4: =EDATE(G4,1) -> 46447 | I4: =EDATE(H4,1) -> 46478 | J4: =EDATE(I4,1) -> 46508 | K4: =EDATE(J4,1) -> 46539 | ... AL4: =EDATE(AK4,1) -> 47362
B6: Site visitors | C6: =Assumptions!$B$25 -> 2000 | D6: =C6*(1+Assumptions!$B$26) -> 2200 | E6: =D6*(1+Assumptions!$B$26) -> 2420 | F6: =E6*(1+Assumptions!$B$26) -> 2662 | G6: =F6*(1+Assumptions!$B$26) -> 2928.2 | H6: =G6*(1+Assumptions!$B$26) -> 3221.02 | I6: =H6*(1+Assumptions!$B$26) -> 3543.122 | J6: =I6*(1+Assumptions!$B$26) -> 3897.4342 | K6: =J6*(1+Assumptions!$B$26) -> 4287.1776 | ... AL6: =AK6*(1+Assumptions!$B$26) -> 56204.874
B7: Free full-manuscript analyses | C7: =C6*Assumptions!$B$27 -> 100 | D7: =D6*Assumptions!$B$27 -> 110 | E7: =E6*Assumptions!$B$27 -> 121 | F7: =F6*Assumptions!$B$27 -> 133.1 | G7: =G6*Assumptions!$B$27 -> 146.41 | H7: =H6*Assumptions!$B$27 -> 161.051 | I7: =I6*Assumptions!$B$27 -> 177.1561 | J7: =J6*Assumptions!$B$27 -> 194.87171 | ... AL7: =AL6*Assumptions!$B$27 -> 2810.2437
B8: New paid subscribers | C8: =C7*Assumptions!$B$28 -> 8 | D8: =D7*Assumptions!$B$28 -> 8.8 | E8: =E7*Assumptions!$B$28 -> 9.68 | F8: =F7*Assumptions!$B$28 -> 10.648 | G8: =G7*Assumptions!$B$28 -> 11.7128 | H8: =H7*Assumptions!$B$28 -> 12.88408 | I8: =I7*Assumptions!$B$28 -> 14.172488 | J8: =J7*Assumptions!$B$28 -> 15.589737 | ... AL8: =AL7*Assumptions!$B$28 -> 224.81949
B9: of which Starter | C9: =C8*Assumptions!$B$29 -> 3.2 | D9: =D8*Assumptions!$B$29 -> 3.52 | E9: =E8*Assumptions!$B$29 -> 3.872 | F9: =F8*Assumptions!$B$29 -> 4.2592 | G9: =G8*Assumptions!$B$29 -> 4.68512 | H9: =H8*Assumptions!$B$29 -> 5.153632 | I9: =I8*Assumptions!$B$29 -> 5.6689952 | J9: =J8*Assumptions!$B$29 -> 6.2358947 | ... AL9: =AL8*Assumptions!$B$29 -> 89.927798
B10: of which Author | C10: =C8*Assumptions!$B$30 -> 3.6 | D10: =D8*Assumptions!$B$30 -> 3.96 | E10: =E8*Assumptions!$B$30 -> 4.356 | F10: =F8*Assumptions!$B$30 -> 4.7916 | G10: =G8*Assumptions!$B$30 -> 5.27076 | H10: =H8*Assumptions!$B$30 -> 5.797836 | I10: =I8*Assumptions!$B$30 -> 6.3776196 | J10: =J8*Assumptions!$B$30 -> 7.0153816 | ... AL10: =AL8*Assumptions!$B$30 -> 101.16877
B11: of which Pro | C11: =C8*Assumptions!$B$31 -> 1.2 | D11: =D8*Assumptions!$B$31 -> 1.32 | E11: =E8*Assumptions!$B$31 -> 1.452 | F11: =F8*Assumptions!$B$31 -> 1.5972 | G11: =G8*Assumptions!$B$31 -> 1.75692 | H11: =H8*Assumptions!$B$31 -> 1.932612 | I11: =I8*Assumptions!$B$31 -> 2.1258732 | J11: =J8*Assumptions!$B$31 -> 2.3384605 | ... AL11: =AL8*Assumptions!$B$31 -> 33.722924
B12: One-time passes sold | C12: =C7*Assumptions!$B$32 -> 2 | D12: =D7*Assumptions!$B$32 -> 2.2 | E12: =E7*Assumptions!$B$32 -> 2.42 | F12: =F7*Assumptions!$B$32 -> 2.662 | G12: =G7*Assumptions!$B$32 -> 2.9282 | H12: =H7*Assumptions!$B$32 -> 3.22102 | I12: =I7*Assumptions!$B$32 -> 3.543122 | J12: =J7*Assumptions!$B$32 -> 3.8974342 | ... AL12: =AL7*Assumptions!$B$32 -> 56.204874
B14: STARTER — opening | C14: 0 | D14: =C17 -> 3.2 | E14: =D17 -> 6.464 | F14: =E17 -> 9.81888 | G14: =F17 -> 13.29257 | H14: =G17 -> 16.914284 | I14: =H17 -> 20.714773 | J14: =I17 -> 24.726587 | K14: =J17 -> 28.984354 | ... AL14: =AK17 -> 498.63848
B15: adds | C15: =C9 -> 3.2 | D15: =D9 -> 3.52 | E15: =E9 -> 3.872 | F15: =F9 -> 4.2592 | G15: =G9 -> 4.68512 | H15: =H9 -> 5.153632 | I15: =I9 -> 5.6689952 | J15: =J9 -> 6.2358947 | ... AL15: =AL9 -> 89.927798
B16: churned | C16: =C14*Assumptions!$B$35 -> 0 | D16: =D14*Assumptions!$B$35 -> 0.256 | E16: =E14*Assumptions!$B$35 -> 0.51712 | F16: =F14*Assumptions!$B$35 -> 0.7855104 | G16: =G14*Assumptions!$B$35 -> 1.0634056 | H16: =H14*Assumptions!$B$35 -> 1.3531427 | I16: =I14*Assumptions!$B$35 -> 1.6571819 | J16: =J14*Assumptions!$B$35 -> 1.9781269 | ... AL16: =AL14*Assumptions!$B$35 -> 39.891078
B17: closing | C17: =C14+C15-C16 -> 3.2 | D17: =D14+D15-D16 -> 6.464 | E17: =E14+E15-E16 -> 9.81888 | F17: =F14+F15-F16 -> 13.29257 | G17: =G14+G15-G16 -> 16.914284 | H17: =H14+H15-H16 -> 20.714773 | I17: =I14+I15-I16 -> 24.726587 | J17: =J14+J15-J16 -> 28.984354 | ... AL17: =AL14+AL15-AL16 -> 548.6752
B19: AUTHOR — opening | C19: 0 | D19: =C22 -> 3.6 | E19: =D22 -> 7.38 | F19: =E22 -> 11.367 | G19: =F22 -> 15.59025 | H19: =G22 -> 20.081498 | I19: =H22 -> 24.875259 | J19: =I22 -> 30.009115 | K19: =J22 -> 35.524041 | ... AL19: =AK22 -> 670.47248
B20: adds | C20: =C10 -> 3.6 | D20: =D10 -> 3.96 | E20: =E10 -> 4.356 | F20: =F10 -> 4.7916 | G20: =G10 -> 5.27076 | H20: =H10 -> 5.797836 | I20: =I10 -> 6.3776196 | J20: =J10 -> 7.0153816 | ... AL20: =AL10 -> 101.16877
B21: churned | C21: =C19*Assumptions!$B$36 -> 0 | D21: =D19*Assumptions!$B$36 -> 0.18 | E21: =E19*Assumptions!$B$36 -> 0.369 | F21: =F19*Assumptions!$B$36 -> 0.56835 | G21: =G19*Assumptions!$B$36 -> 0.7795125 | H21: =H19*Assumptions!$B$36 -> 1.0040749 | I21: =I19*Assumptions!$B$36 -> 1.2437629 | J21: =J19*Assumptions!$B$36 -> 1.5004558 | ... AL21: =AL19*Assumptions!$B$36 -> 33.523624
B22: closing | C22: =C19+C20-C21 -> 3.6 | D22: =D19+D20-D21 -> 7.38 | E22: =E19+E20-E21 -> 11.367 | F22: =F19+F20-F21 -> 15.59025 | G22: =G19+G20-G21 -> 20.081498 | H22: =H19+H20-H21 -> 24.875259 | I22: =I19+I20-I21 -> 30.009115 | J22: =J19+J20-J21 -> 35.524041 | ... AL22: =AL19+AL20-AL21 -> 738.11763
B24: PRO — opening | C24: 0 | D24: =C27 -> 1.2 | E24: =D27 -> 2.484 | F24: =E27 -> 3.86148 | G24: =F27 -> 5.3428356 | H24: =G27 -> 6.9394705 | I24: =H27 -> 8.6638984 | J24: =I27 -> 10.529855 | K24: =J27 -> 12.55242 | ... AL24: =AK27 -> 256.22842
B25: adds | C25: =C11 -> 1.2 | D25: =D11 -> 1.32 | E25: =E11 -> 1.452 | F25: =F11 -> 1.5972 | G25: =G11 -> 1.75692 | H25: =H11 -> 1.932612 | I25: =I11 -> 2.1258732 | J25: =J11 -> 2.3384605 | ... AL25: =AL11 -> 33.722924
B26: churned | C26: =C24*Assumptions!$B$37 -> 0 | D26: =D24*Assumptions!$B$37 -> 0.036 | E26: =E24*Assumptions!$B$37 -> 0.07452 | F26: =F24*Assumptions!$B$37 -> 0.1158444 | G26: =G24*Assumptions!$B$37 -> 0.16028507 | H26: =H24*Assumptions!$B$37 -> 0.20818412 | I26: =I24*Assumptions!$B$37 -> 0.25991695 | J26: =J24*Assumptions!$B$37 -> 0.31589564 | ... AL26: =AL24*Assumptions!$B$37 -> 7.6868525
B27: closing | C27: =C24+C25-C26 -> 1.2 | D27: =D24+D25-D26 -> 2.484 | E27: =E24+E25-E26 -> 3.86148 | F27: =F24+F25-F26 -> 5.3428356 | G27: =G24+G25-G26 -> 6.9394705 | H27: =H24+H25-H26 -> 8.6638984 | I27: =I24+I25-I26 -> 10.529855 | J27: =J24+J25-J26 -> 12.55242 | ... AL27: =AL24+AL25-AL26 -> 282.26449
B29: GRANDFATHERED — opening | C29: =Assumptions!$B$22 -> 11 | D29: =C31 -> 10.67 | E29: =D31 -> 10.3499 | F29: =E31 -> 10.039403 | G29: =F31 -> 9.7382209 | H29: =G31 -> 9.4460743 | I29: =H31 -> 9.1626921 | J29: =I31 -> 8.8878113 | K29: =J31 -> 8.621177 | ... AL29: =AK31 -> 3.7879426
B30: churned | C30: =C29*Assumptions!$B$39 -> 0.33 | D30: =D29*Assumptions!$B$39 -> 0.3201 | E30: =E29*Assumptions!$B$39 -> 0.310497 | F30: =F29*Assumptions!$B$39 -> 0.30118209 | G30: =G29*Assumptions!$B$39 -> 0.29214663 | H30: =H29*Assumptions!$B$39 -> 0.28338223 | I30: =I29*Assumptions!$B$39 -> 0.27488076 | J30: =J29*Assumptions!$B$39 -> 0.26663434 | ... AL30: =AL29*Assumptions!$B$39 -> 0.11363828
B31: closing | C31: =C29-C30 -> 10.67 | D31: =D29-D30 -> 10.3499 | E31: =E29-E30 -> 10.039403 | F31: =F29-F30 -> 9.7382209 | G31: =G29-G30 -> 9.4460743 | H31: =H29-H30 -> 9.1626921 | I31: =I29-I30 -> 8.8878113 | J31: =J29-J30 -> 8.621177 | ... AL31: =AL29-AL30 -> 3.6743043
B33: IMPRINTS — adds (input row) | C33: 0 | D33: 0 | E33: 1 | F33: 0 | G33: 0 | H33: 0 | I33: 0 | J33: 0 | K33: 0 | L33: 0 | M33: 0 | N33: 0 | O33: 0 | P33: 0 | Q33: 0 | R33: 0 | S33: 0 | T33: 0 | U33: 0 | V33: 0 | W33: 0 | X33: 0 | Y33: 0 | Z33: 0 | AA33: 0 | AB33: 0 | AC33: 0 | AD33: 0 | AE33: 0 | AF33: 0 | AG33: 0 | AH33: 0 | AI33: 0 | AJ33: 0 | AK33: 0 | AL33: 0 | AN33: Month 3 = 1: Jacky Klein imprint (ASSUMPTION — September demo converts). Edit adds directly.
B34: opening | C34: 0 | D34: =C36 -> 0 | E34: =D36 -> 0 | F34: =E36 -> 1 | G34: =F36 -> 0.99 | H34: =G36 -> 0.9801 | I34: =H36 -> 0.970299 | J34: =I36 -> 0.96059601 | K34: =J36 -> 0.95099005 | ... AL34: =AK36 -> 0.72498034
B35: churned | C35: =C34*Assumptions!$B$38 -> 0 | D35: =D34*Assumptions!$B$38 -> 0 | E35: =E34*Assumptions!$B$38 -> 0 | F35: =F34*Assumptions!$B$38 -> 0.01 | G35: =G34*Assumptions!$B$38 -> 0.0099 | H35: =H34*Assumptions!$B$38 -> 0.009801 | I35: =I34*Assumptions!$B$38 -> 0.00970299 | J35: =J34*Assumptions!$B$38 -> 0.0096059601 | ... AL35: =AL34*Assumptions!$B$38 -> 0.0072498034
B36: closing | C36: =C34+C33-C35 -> 0 | D36: =D34+D33-D35 -> 0 | E36: =E34+E33-E35 -> 1 | F36: =F34+F33-F35 -> 0.99 | G36: =G34+G33-G35 -> 0.9801 | H36: =H34+H33-H35 -> 0.970299 | I36: =I34+I33-I35 -> 0.96059601 | J36: =J34+J33-J35 -> 0.95099005 | ... AL36: =AL34+AL33-AL35 -> 0.71773053
B38: Total paying writers (closing) | C38: =C17+C22+C27+C31 -> 18.67 | D38: =D17+D22+D27+D31 -> 26.6779 | E38: =E17+E22+E27+E31 -> 35.086763 | F38: =F17+F22+F27+F31 -> 43.963876 | G38: =G17+G22+G27+G31 -> 53.381326 | H38: =H17+H22+H27+H31 -> 63.416622 | I38: =I17+I22+I27+I31 -> 74.153368 | J38: =J17+J22+J27+J31 -> 85.681992 | ... AL38: =AL17+AL22+AL27+AL31 -> 1572.7316
B39: Total accounts incl imprints | C39: =C38+C36 -> 18.67 | D39: =D38+D36 -> 26.6779 | E39: =E38+E36 -> 36.086763 | F39: =F38+F36 -> 44.953876 | G39: =G38+G36 -> 54.361426 | H39: =H38+H36 -> 64.386921 | I39: =I38+I36 -> 75.113964 | J39: =J38+J36 -> 86.632982 | ... AL39: =AL38+AL36 -> 1573.4494

Sheet Revenue
B1: Revenue (GBP)
B3: Month | C3: 1 | D3: 2 | E3: 3 | F3: 4 | G3: 5 | H3: 6 | I3: 7 | J3: 8 | K3: 9 | L3: 10 | M3: 11 | N3: 12 | O3: 13 | P3: 14 | Q3: 15 | R3: 16 | S3: 17 | T3: 18 | U3: 19 | V3: 20 | W3: 21 | X3: 22 | Y3: 23 | Z3: 24 | AA3: 25 | AB3: 26 | AC3: 27 | AD3: 28 | AE3: 29 | AF3: 30 | AG3: 31 | AH3: 32 | AI3: 33 | AJ3: 34 | AK3: 35 | AL3: 36
B4: Period | C4: =Assumptions!$B$5 -> 46296 | D4: =EDATE(C4,1) -> 46327 | E4: =EDATE(D4,1) -> 46357 | F4: =EDATE(E4,1) -> 46388 | G4: =EDATE(F4,1) -> 46419 | H4: =EDATE(G4,1) -> 46447 | I4: =EDATE(H4,1) -> 46478 | J4: =EDATE(I4,1) -> 46508 | K4: =EDATE(J4,1) -> 46539 | ... AL4: =EDATE(AK4,1) -> 47362
B6: Starter MRR | C6: =Funnel!C17*Assumptions!$B$16 -> 28.16 | D6: =Funnel!D17*Assumptions!$B$16 -> 56.8832 | E6: =Funnel!E17*Assumptions!$B$16 -> 86.406144 | F6: =Funnel!F17*Assumptions!$B$16 -> 116.97461 | G6: =Funnel!G17*Assumptions!$B$16 -> 148.8457 | H6: =Funnel!H17*Assumptions!$B$16 -> 182.29001 | I6: =Funnel!I17*Assumptions!$B$16 -> 217.59396 | J6: =Funnel!J17*Assumptions!$B$16 -> 255.06232 | ... AL6: =Funnel!AL17*Assumptions!$B$16 -> 4828.3417
B7: Author MRR | C7: =Funnel!C22*Assumptions!$B$17 -> 59.76 | D7: =Funnel!D22*Assumptions!$B$17 -> 122.508 | E7: =Funnel!E22*Assumptions!$B$17 -> 188.6922 | F7: =Funnel!F22*Assumptions!$B$17 -> 258.79815 | G7: =Funnel!G22*Assumptions!$B$17 -> 333.35286 | H7: =Funnel!H22*Assumptions!$B$17 -> 412.92929 | I7: =Funnel!I22*Assumptions!$B$17 -> 498.15131 | J7: =Funnel!J22*Assumptions!$B$17 -> 589.69908 | ... AL7: =Funnel!AL22*Assumptions!$B$17 -> 12252.753
B8: Pro MRR | C8: =Funnel!C27*Assumptions!$B$18 -> 41.04 | D8: =Funnel!D27*Assumptions!$B$18 -> 84.9528 | E8: =Funnel!E27*Assumptions!$B$18 -> 132.06262 | F8: =Funnel!F27*Assumptions!$B$18 -> 182.72498 | G8: =Funnel!G27*Assumptions!$B$18 -> 237.32989 | H8: =Funnel!H27*Assumptions!$B$18 -> 296.30533 | I8: =Funnel!I27*Assumptions!$B$18 -> 360.12103 | J8: =Funnel!J27*Assumptions!$B$18 -> 429.29275 | ... AL8: =Funnel!AL27*Assumptions!$B$18 -> 9653.4455
B9: Grandfathered MRR | C9: =Funnel!C31*Assumptions!$B$21 -> 101.365 | D9: =Funnel!D31*Assumptions!$B$21 -> 98.32405 | E9: =Funnel!E31*Assumptions!$B$21 -> 95.374329 | F9: =Funnel!F31*Assumptions!$B$21 -> 92.513099 | G9: =Funnel!G31*Assumptions!$B$21 -> 89.737706 | H9: =Funnel!H31*Assumptions!$B$21 -> 87.045575 | I9: =Funnel!I31*Assumptions!$B$21 -> 84.434207 | J9: =Funnel!J31*Assumptions!$B$21 -> 81.901181 | ... AL9: =Funnel!AL31*Assumptions!$B$21 -> 34.905891
B10: Writer MRR | C10: =SUM(C6:C9) -> 230.325 | D10: =SUM(D6:D9) -> 362.66805 | E10: =SUM(E6:E9) -> 502.53529 | F10: =SUM(F6:F9) -> 651.01084 | G10: =SUM(G6:G9) -> 809.26616 | H10: =SUM(H6:H9) -> 978.5702 | I10: =SUM(I6:I9) -> 1160.3005 | J10: =SUM(J6:J9) -> 1355.9553 | ... AL10: =SUM(AL6:AL9) -> 26769.446
B11: Imprint MRR | C11: =Funnel!C36*Assumptions!$B$20 -> 0 | D11: =Funnel!D36*Assumptions!$B$20 -> 0 | E11: =Funnel!E36*Assumptions!$B$20 -> 500 | F11: =Funnel!F36*Assumptions!$B$20 -> 495 | G11: =Funnel!G36*Assumptions!$B$20 -> 490.05 | H11: =Funnel!H36*Assumptions!$B$20 -> 485.1495 | I11: =Funnel!I36*Assumptions!$B$20 -> 480.298 | J11: =Funnel!J36*Assumptions!$B$20 -> 475.49502 | ... AL11: =Funnel!AL36*Assumptions!$B$20 -> 358.86527
B12: Total MRR | C12: =C10+C11 -> 230.325 | D12: =D10+D11 -> 362.66805 | E12: =E10+E11 -> 1002.5353 | F12: =F10+F11 -> 1146.0108 | G12: =G10+G11 -> 1299.3162 | H12: =H10+H11 -> 1463.7197 | I12: =I10+I11 -> 1640.5985 | J12: =J10+J11 -> 1831.4504 | ... AL12: =AL10+AL11 -> 27128.311
B13: One-time pass revenue | C13: =Funnel!C12*Assumptions!$B$19 -> 238 | D13: =Funnel!D12*Assumptions!$B$19 -> 261.8 | E13: =Funnel!E12*Assumptions!$B$19 -> 287.98 | F13: =Funnel!F12*Assumptions!$B$19 -> 316.778 | G13: =Funnel!G12*Assumptions!$B$19 -> 348.4558 | H13: =Funnel!H12*Assumptions!$B$19 -> 383.30138 | I13: =Funnel!I12*Assumptions!$B$19 -> 421.63152 | J13: =Funnel!J12*Assumptions!$B$19 -> 463.79467 | ... AL13: =Funnel!AL12*Assumptions!$B$19 -> 6688.38
B14: TOTAL REVENUE | C14: =C12+C13 -> 468.325 | D14: =D12+D13 -> 624.46805 | E14: =E12+E13 -> 1290.5153 | F14: =F12+F13 -> 1462.7888 | G14: =G12+G13 -> 1647.772 | H14: =H12+H13 -> 1847.0211 | I14: =I12+I13 -> 2062.23 | J14: =J12+J13 -> 2295.245 | ... AL14: =AL12+AL13 -> 33816.691
B15: ARR run-rate | C15: =C12*12 -> 2763.9 | D15: =D12*12 -> 4352.0166 | E15: =E12*12 -> 12030.423 | F15: =F12*12 -> 13752.13 | G15: =G12*12 -> 15591.794 | H15: =H12*12 -> 17564.636 | I15: =I12*12 -> 19687.182 | J15: =J12*12 -> 21977.404 | ... AL15: =AL12*12 -> 325539.73

Sheet COGS
B1: COGS (GBP) — deep-pass lines are INSTRUMENT lines (lmo_ledger)
B3: Month | C3: 1 | D3: 2 | E3: 3 | F3: 4 | G3: 5 | H3: 6 | I3: 7 | J3: 8 | K3: 9 | L3: 10 | M3: 11 | N3: 12 | O3: 13 | P3: 14 | Q3: 15 | R3: 16 | S3: 17 | T3: 18 | U3: 19 | V3: 20 | W3: 21 | X3: 22 | Y3: 23 | Z3: 24 | AA3: 25 | AB3: 26 | AC3: 27 | AD3: 28 | AE3: 29 | AF3: 30 | AG3: 31 | AH3: 32 | AI3: 33 | AJ3: 34 | AK3: 35 | AL3: 36
B4: Period | C4: =Assumptions!$B$5 -> 46296 | D4: =EDATE(C4,1) -> 46327 | E4: =EDATE(D4,1) -> 46357 | F4: =EDATE(E4,1) -> 46388 | G4: =EDATE(F4,1) -> 46419 | H4: =EDATE(G4,1) -> 46447 | I4: =EDATE(H4,1) -> 46478 | J4: =EDATE(I4,1) -> 46508 | K4: =EDATE(J4,1) -> 46539 | ... AL4: =EDATE(AK4,1) -> 47362
B6: Deep passes — Starter | C6: =Funnel!C17*Assumptions!$B$44*Assumptions!$B$47 -> 1.92 | D6: =Funnel!D17*Assumptions!$B$44*Assumptions!$B$47 -> 3.8784 | E6: =Funnel!E17*Assumptions!$B$44*Assumptions!$B$47 -> 5.891328 | F6: =Funnel!F17*Assumptions!$B$44*Assumptions!$B$47 -> 7.9755418 | G6: =Funnel!G17*Assumptions!$B$44*Assumptions!$B$47 -> 10.14857 | H6: =Funnel!H17*Assumptions!$B$44*Assumptions!$B$47 -> 12.428864 | I6: =Funnel!I17*Assumptions!$B$44*Assumptions!$B$47 -> 14.835952 | J6: =Funnel!J17*Assumptions!$B$44*Assumptions!$B$47 -> 17.390613 | ... AL6: =Funnel!AL17*Assumptions!$B$44*Assumptions!$B$47 -> 329.20512
B7: Deep passes — Author | C7: =Funnel!C22*Assumptions!$B$45*Assumptions!$B$47 -> 8.64 | D7: =Funnel!D22*Assumptions!$B$45*Assumptions!$B$47 -> 17.712 | E7: =Funnel!E22*Assumptions!$B$45*Assumptions!$B$47 -> 27.2808 | F7: =Funnel!F22*Assumptions!$B$45*Assumptions!$B$47 -> 37.4166 | G7: =Funnel!G22*Assumptions!$B$45*Assumptions!$B$47 -> 48.195594 | H7: =Funnel!H22*Assumptions!$B$45*Assumptions!$B$47 -> 59.700621 | I7: =Funnel!I22*Assumptions!$B$45*Assumptions!$B$47 -> 72.021877 | J7: =Funnel!J22*Assumptions!$B$45*Assumptions!$B$47 -> 85.257699 | ... AL7: =Funnel!AL22*Assumptions!$B$45*Assumptions!$B$47 -> 1771.4823
B8: Deep passes — Pro | C8: =Funnel!C27*Assumptions!$B$46*Assumptions!$B$47 -> 7.2 | D8: =Funnel!D27*Assumptions!$B$46*Assumptions!$B$47 -> 14.904 | E8: =Funnel!E27*Assumptions!$B$46*Assumptions!$B$47 -> 23.16888 | F8: =Funnel!F27*Assumptions!$B$46*Assumptions!$B$47 -> 32.057014 | G8: =Funnel!G27*Assumptions!$B$46*Assumptions!$B$47 -> 41.636823 | H8: =Funnel!H27*Assumptions!$B$46*Assumptions!$B$47 -> 51.98339 | I8: =Funnel!I27*Assumptions!$B$46*Assumptions!$B$47 -> 63.179128 | J8: =Funnel!J27*Assumptions!$B$46*Assumptions!$B$47 -> 75.314517 | ... AL8: =Funnel!AL27*Assumptions!$B$46*Assumptions!$B$47 -> 1693.5869
B9: Deep passes — Grandfathered | C9: =Funnel!C31*Assumptions!$B$45*Assumptions!$B$47 -> 25.608 | D9: =Funnel!D31*Assumptions!$B$45*Assumptions!$B$47 -> 24.83976 | E9: =Funnel!E31*Assumptions!$B$45*Assumptions!$B$47 -> 24.094567 | F9: =Funnel!F31*Assumptions!$B$45*Assumptions!$B$47 -> 23.37173 | G9: =Funnel!G31*Assumptions!$B$45*Assumptions!$B$47 -> 22.670578 | H9: =Funnel!H31*Assumptions!$B$45*Assumptions!$B$47 -> 21.990461 | I9: =Funnel!I31*Assumptions!$B$45*Assumptions!$B$47 -> 21.330747 | J9: =Funnel!J31*Assumptions!$B$45*Assumptions!$B$47 -> 20.690825 | ... AL9: =Funnel!AL31*Assumptions!$B$45*Assumptions!$B$47 -> 8.8183303
B10: Total deep passes consumed | C10: =SUM(C6:C9) -> 43.368 | D10: =SUM(D6:D9) -> 61.33416 | E10: =SUM(E6:E9) -> 80.435575 | F10: =SUM(F6:F9) -> 100.82089 | G10: =SUM(G6:G9) -> 122.65157 | H10: =SUM(H6:H9) -> 146.10334 | I10: =SUM(I6:I9) -> 171.3677 | J10: =SUM(J6:J9) -> 198.65365 | ... AL10: =SUM(AL6:AL9) -> 3803.0927
B11: Deep-pass AI cost [INSTRUMENT] | C11: =C10*Assumptions!$B$42 -> 130.104 | D11: =D10*Assumptions!$B$42 -> 184.00248 | E11: =E10*Assumptions!$B$42 -> 241.30673 | F11: =F10*Assumptions!$B$42 -> 302.46266 | G11: =G10*Assumptions!$B$42 -> 367.9547 | H11: =H10*Assumptions!$B$42 -> 438.31001 | I11: =I10*Assumptions!$B$42 -> 514.10311 | J11: =J10*Assumptions!$B$42 -> 595.96096 | ... AL11: =AL10*Assumptions!$B$42 -> 11409.278
B12: Non-pass AI cost [INSTRUMENT] | C12: =Funnel!C38*Assumptions!$B$43 -> 28.005 | D12: =Funnel!D38*Assumptions!$B$43 -> 40.01685 | E12: =Funnel!E38*Assumptions!$B$43 -> 52.630145 | F12: =Funnel!F38*Assumptions!$B$43 -> 65.945814 | G12: =Funnel!G38*Assumptions!$B$43 -> 80.07199 | H12: =Funnel!H38*Assumptions!$B$43 -> 95.124934 | I12: =Funnel!I38*Assumptions!$B$43 -> 111.23005 | J12: =Funnel!J38*Assumptions!$B$43 -> 128.52299 | ... AL12: =Funnel!AL38*Assumptions!$B$43 -> 2359.0974
B13: Infrastructure | C13: =Funnel!C39*Assumptions!$B$48 -> 5.601 | D13: =Funnel!D39*Assumptions!$B$48 -> 8.00337 | E13: =Funnel!E39*Assumptions!$B$48 -> 10.826029 | F13: =Funnel!F39*Assumptions!$B$48 -> 13.486163 | G13: =Funnel!G39*Assumptions!$B$48 -> 16.308428 | H13: =Funnel!H39*Assumptions!$B$48 -> 19.316076 | I13: =Funnel!I39*Assumptions!$B$48 -> 22.534189 | J13: =Funnel!J39*Assumptions!$B$48 -> 25.989895 | ... AL13: =Funnel!AL39*Assumptions!$B$48 -> 472.03481
B14: Imprint COGS [INSTRUMENT] | C14: =Funnel!C36*Assumptions!$B$50 -> 0 | D14: =Funnel!D36*Assumptions!$B$50 -> 0 | E14: =Funnel!E36*Assumptions!$B$50 -> 60 | F14: =Funnel!F36*Assumptions!$B$50 -> 59.4 | G14: =Funnel!G36*Assumptions!$B$50 -> 58.806 | H14: =Funnel!H36*Assumptions!$B$50 -> 58.21794 | I14: =Funnel!I36*Assumptions!$B$50 -> 57.635761 | J14: =Funnel!J36*Assumptions!$B$50 -> 57.059403 | ... AL14: =Funnel!AL36*Assumptions!$B$50 -> 43.063832
B15: Payment processing | C15: =Revenue!C14*Assumptions!$B$49 -> 14.9864 | D15: =Revenue!D14*Assumptions!$B$49 -> 19.982978 | E15: =Revenue!E14*Assumptions!$B$49 -> 41.296489 | F15: =Revenue!F14*Assumptions!$B$49 -> 46.809243 | G15: =Revenue!G14*Assumptions!$B$49 -> 52.728703 | H15: =Revenue!H14*Assumptions!$B$49 -> 59.104675 | I15: =Revenue!I14*Assumptions!$B$49 -> 65.991361 | J15: =Revenue!J14*Assumptions!$B$49 -> 73.447841 | ... AL15: =Revenue!AL14*Assumptions!$B$49 -> 1082.1341
B16: TOTAL COGS | C16: =SUM(C11:C15) -> 178.6964 | D16: =SUM(D11:D15) -> 252.00568 | E16: =SUM(E11:E15) -> 406.05939 | F16: =SUM(F11:F15) -> 488.10388 | G16: =SUM(G11:G15) -> 575.86982 | H16: =SUM(H11:H15) -> 670.07363 | I16: =SUM(I11:I15) -> 771.49447 | J16: =SUM(J11:J15) -> 880.98109 | ... AL16: =SUM(AL11:AL15) -> 15365.608
B17: Gross profit | C17: =Revenue!C14-C16 -> 289.6286 | D17: =Revenue!D14-D16 -> 372.46237 | E17: =Revenue!E14-E16 -> 884.4559 | F17: =Revenue!F14-F16 -> 974.68496 | G17: =Revenue!G14-G16 -> 1071.9021 | H17: =Revenue!H14-H16 -> 1176.9474 | I17: =Revenue!I14-I16 -> 1290.7356 | J17: =Revenue!J14-J16 -> 1414.2639 | ... AL17: =Revenue!AL14-AL16 -> 18451.083
B18: Gross margin % | C18: =IF(Revenue!C14=0,0,C17/Revenue!C14) -> 0.61843506 | D18: =IF(Revenue!D14=0,0,D17/Revenue!D14) -> 0.59644744 | E18: =IF(Revenue!E14=0,0,E17/Revenue!E14) -> 0.68535097 | F18: =IF(Revenue!F14=0,0,F17/Revenue!F14) -> 0.66631966 | G18: =IF(Revenue!G14=0,0,G17/Revenue!G14) -> 0.65051607 | H18: =IF(Revenue!H14=0,0,H17/Revenue!H14) -> 0.63721387 | I18: =IF(Revenue!I14=0,0,I17/Revenue!I14) -> 0.62589311 | J18: =IF(Revenue!J14=0,0,J17/Revenue!J14) -> 0.61617123 | ... AL18: =IF(Revenue!AL14=0,0,AL17/Revenue!AL14) -> 0.54562059

Sheet P&L
B1: P&L (GBP, monthly + annual roll-up)
B3: Month | C3: 1 | D3: 2 | E3: 3 | F3: 4 | G3: 5 | H3: 6 | I3: 7 | J3: 8 | K3: 9 | L3: 10 | M3: 11 | N3: 12 | O3: 13 | P3: 14 | Q3: 15 | R3: 16 | S3: 17 | T3: 18 | U3: 19 | V3: 20 | W3: 21 | X3: 22 | Y3: 23 | Z3: 24 | AA3: 25 | AB3: 26 | AC3: 27 | AD3: 28 | AE3: 29 | AF3: 30 | AG3: 31 | AH3: 32 | AI3: 33 | AJ3: 34 | AK3: 35 | AL3: 36 | AN3: Y1 | AO3: Y2 | AP3: Y3 | AQ3: Total
B4: Period | C4: =Assumptions!$B$5 -> 46296 | D4: =EDATE(C4,1) -> 46327 | E4: =EDATE(D4,1) -> 46357 | F4: =EDATE(E4,1) -> 46388 | G4: =EDATE(F4,1) -> 46419 | H4: =EDATE(G4,1) -> 46447 | I4: =EDATE(H4,1) -> 46478 | J4: =EDATE(I4,1) -> 46508 | K4: =EDATE(J4,1) -> 46539 | ... AL4: =EDATE(AK4,1) -> 47362
B6: Revenue | C6: =Revenue!C14 -> 468.325 | D6: =Revenue!D14 -> 624.46805 | E6: =Revenue!E14 -> 1290.5153 | F6: =Revenue!F14 -> 1462.7888 | G6: =Revenue!G14 -> 1647.772 | H6: =Revenue!H14 -> 1847.0211 | I6: =Revenue!I14 -> 2062.23 | J6: =Revenue!J14 -> 2295.245 | ... AL6: =Revenue!AL14 -> 33816.691 | AN6: =SUM(C6:N6) -> 23640.199 | AO6: =SUM(O6:Z6) -> 81628.389 | AP6: =SUM(AA6:AL6) -> 254204.3 | AQ6: =SUM(AN6:AP6) -> 359472.89
B7: COGS | C7: =COGS!C16 -> 178.6964 | D7: =COGS!D16 -> 252.00568 | E7: =COGS!E16 -> 406.05939 | F7: =COGS!F16 -> 488.10388 | G7: =COGS!G16 -> 575.86982 | H7: =COGS!H16 -> 670.07363 | I7: =COGS!I16 -> 771.49447 | J7: =COGS!J16 -> 880.98109 | ... AL7: =COGS!AL16 -> 15365.608 | AN7: =SUM(C7:N7) -> 9037.6504 | AO7: =SUM(O7:Z7) -> 35629.549 | AP7: =SUM(AA7:AL7) -> 114890.94 | AQ7: =SUM(AN7:AP7) -> 159558.14
B8: Gross profit | C8: =C6-C7 -> 289.6286 | D8: =D6-D7 -> 372.46237 | E8: =E6-E7 -> 884.4559 | F8: =F6-F7 -> 974.68496 | G8: =G6-G7 -> 1071.9021 | H8: =H6-H7 -> 1176.9474 | I8: =I6-I7 -> 1290.7356 | J8: =J6-J7 -> 1414.2639 | ... AL8: =AL6-AL7 -> 18451.083 | AN8: =SUM(C8:N8) -> 14602.549 | AO8: =SUM(O8:Z8) -> 45998.84 | AP8: =SUM(AA8:AL8) -> 139313.36 | AQ8: =SUM(AN8:AP8) -> 199914.75
B9: Gross margin % | C9: =IF(C6=0,0,C8/C6) -> 0.61843506 | D9: =IF(D6=0,0,D8/D6) -> 0.59644744 | E9: =IF(E6=0,0,E8/E6) -> 0.68535097 | F9: =IF(F6=0,0,F8/F6) -> 0.66631966 | G9: =IF(G6=0,0,G8/G6) -> 0.65051607 | H9: =IF(H6=0,0,H8/H6) -> 0.63721387 | I9: =IF(I6=0,0,I8/I6) -> 0.62589311 | J9: =IF(J6=0,0,J8/J6) -> 0.61617123 | ... AL9: =IF(AL6=0,0,AL8/AL6) -> 0.54562059 | AN9: =IF(AN6=0,0,AN8/AN6) -> 0.61769991 | AO9: =IF(AO6=0,0,AO8/AO6) -> 0.56351523 | AP9: =IF(AP6=0,0,AP8/AP6) -> 0.54803699 | AQ9: =IF(AQ6=0,0,AQ8/AQ6) -> 0.55613304
B11: Team | C11: =Assumptions!$B$53 -> 8000 | D11: =Assumptions!$B$53 -> 8000 | E11: =Assumptions!$B$53 -> 8000 | F11: =Assumptions!$B$53 -> 8000 | G11: =Assumptions!$B$53 -> 8000 | H11: =Assumptions!$B$53 -> 8000 | I11: =Assumptions!$B$53 -> 8000 | J11: =Assumptions!$B$53 -> 8000 | ... AL11: =Assumptions!$B$53 -> 8000 | AN11: =SUM(C11:N11) -> 96000 | AO11: =SUM(O11:Z11) -> 96000 | AP11: =SUM(AA11:AL11) -> 96000 | AQ11: =SUM(AN11:AP11) -> 288000
B12: Tools & hosting | C12: =Assumptions!$B$54 -> 500 | D12: =Assumptions!$B$54 -> 500 | E12: =Assumptions!$B$54 -> 500 | F12: =Assumptions!$B$54 -> 500 | G12: =Assumptions!$B$54 -> 500 | H12: =Assumptions!$B$54 -> 500 | I12: =Assumptions!$B$54 -> 500 | J12: =Assumptions!$B$54 -> 500 | ... AL12: =Assumptions!$B$54 -> 500 | AN12: =SUM(C12:N12) -> 6000 | AO12: =SUM(O12:Z12) -> 6000 | AP12: =SUM(AA12:AL12) -> 6000 | AQ12: =SUM(AN12:AP12) -> 18000
B13: Marketing | C13: =Assumptions!$B$55 -> 1500 | D13: =Assumptions!$B$55 -> 1500 | E13: =Assumptions!$B$55 -> 1500 | F13: =Assumptions!$B$55 -> 1500 | G13: =Assumptions!$B$55 -> 1500 | H13: =Assumptions!$B$55 -> 1500 | I13: =Assumptions!$B$55 -> 1500 | J13: =Assumptions!$B$55 -> 1500 | ... AL13: =Assumptions!$B$55 -> 1500 | AN13: =SUM(C13:N13) -> 18000 | AO13: =SUM(O13:Z13) -> 18000 | AP13: =SUM(AA13:AL13) -> 18000 | AQ13: =SUM(AN13:AP13) -> 54000
B14: Other | C14: =Assumptions!$B$56 -> 500 | D14: =Assumptions!$B$56 -> 500 | E14: =Assumptions!$B$56 -> 500 | F14: =Assumptions!$B$56 -> 500 | G14: =Assumptions!$B$56 -> 500 | H14: =Assumptions!$B$56 -> 500 | I14: =Assumptions!$B$56 -> 500 | J14: =Assumptions!$B$56 -> 500 | ... AL14: =Assumptions!$B$56 -> 500 | AN14: =SUM(C14:N14) -> 6000 | AO14: =SUM(O14:Z14) -> 6000 | AP14: =SUM(AA14:AL14) -> 6000 | AQ14: =SUM(AN14:AP14) -> 18000
B15: Total opex | C15: =SUM(C11:C14) -> 10500 | D15: =SUM(D11:D14) -> 10500 | E15: =SUM(E11:E14) -> 10500 | F15: =SUM(F11:F14) -> 10500 | G15: =SUM(G11:G14) -> 10500 | H15: =SUM(H11:H14) -> 10500 | I15: =SUM(I11:I14) -> 10500 | J15: =SUM(J11:J14) -> 10500 | ... AL15: =SUM(AL11:AL14) -> 10500 | AN15: =SUM(C15:N15) -> 126000 | AO15: =SUM(O15:Z15) -> 126000 | AP15: =SUM(AA15:AL15) -> 126000 | AQ15: =SUM(AN15:AP15) -> 378000
B17: EBITDA | C17: =C8-C15 -> -10210.371 | D17: =D8-D15 -> -10127.538 | E17: =E8-E15 -> -9615.5441 | F17: =F8-F15 -> -9525.315 | G17: =G8-G15 -> -9428.0979 | H17: =H8-H15 -> -9323.0526 | I17: =I8-I15 -> -9209.2644 | J17: =J8-J15 -> -9085.7361 | ... AL17: =AL8-AL15 -> 7951.0828 | AN17: =SUM(C17:N17) -> -111397.45 | AO17: =SUM(O17:Z17) -> -80001.16 | AP17: =SUM(AA17:AL17) -> 13313.359 | AQ17: =SUM(AN17:AP17) -> -178085.25
B18: Cumulative EBITDA | C18: =C17 -> -10210.371 | D18: =C18+D17 -> -20337.909 | E18: =D18+E17 -> -29953.453 | F18: =E18+F17 -> -39478.768 | G18: =F18+G17 -> -48906.866 | H18: =G18+H17 -> -58229.919 | I18: =H18+I17 -> -67439.183 | J18: =I18+J17 -> -76524.919 | K18: =J18+K17 -> -85476.297 | ... AL18: =AK18+AL17 -> -178085.25

Sheet Metrics
B1: Metrics
B3: Month | C3: 1 | D3: 2 | E3: 3 | F3: 4 | G3: 5 | H3: 6 | I3: 7 | J3: 8 | K3: 9 | L3: 10 | M3: 11 | N3: 12 | O3: 13 | P3: 14 | Q3: 15 | R3: 16 | S3: 17 | T3: 18 | U3: 19 | V3: 20 | W3: 21 | X3: 22 | Y3: 23 | Z3: 24 | AA3: 25 | AB3: 26 | AC3: 27 | AD3: 28 | AE3: 29 | AF3: 30 | AG3: 31 | AH3: 32 | AI3: 33 | AJ3: 34 | AK3: 35 | AL3: 36
B4: Period | C4: =Assumptions!$B$5 -> 46296 | D4: =EDATE(C4,1) -> 46327 | E4: =EDATE(D4,1) -> 46357 | F4: =EDATE(E4,1) -> 46388 | G4: =EDATE(F4,1) -> 46419 | H4: =EDATE(G4,1) -> 46447 | I4: =EDATE(H4,1) -> 46478 | J4: =EDATE(I4,1) -> 46508 | K4: =EDATE(J4,1) -> 46539 | ... AL4: =EDATE(AK4,1) -> 47362
B6: Paying writers (closing) | C6: =Funnel!C38 -> 18.67 | D6: =Funnel!D38 -> 26.6779 | E6: =Funnel!E38 -> 35.086763 | F6: =Funnel!F38 -> 43.963876 | G6: =Funnel!G38 -> 53.381326 | H6: =Funnel!H38 -> 63.416622 | I6: =Funnel!I38 -> 74.153368 | J6: =Funnel!J38 -> 85.681992 | ... AL6: =Funnel!AL38 -> 1572.7316
B7: Imprints (closing) | C7: =Funnel!C36 -> 0 | D7: =Funnel!D36 -> 0 | E7: =Funnel!E36 -> 1 | F7: =Funnel!F36 -> 0.99 | G7: =Funnel!G36 -> 0.9801 | H7: =Funnel!H36 -> 0.970299 | I7: =Funnel!I36 -> 0.96059601 | J7: =Funnel!J36 -> 0.95099005 | ... AL7: =Funnel!AL36 -> 0.71773053
B8: Total MRR | C8: =Revenue!C12 -> 230.325 | D8: =Revenue!D12 -> 362.66805 | E8: =Revenue!E12 -> 1002.5353 | F8: =Revenue!F12 -> 1146.0108 | G8: =Revenue!G12 -> 1299.3162 | H8: =Revenue!H12 -> 1463.7197 | I8: =Revenue!I12 -> 1640.5985 | J8: =Revenue!J12 -> 1831.4504 | ... AL8: =Revenue!AL12 -> 27128.311
B9: ARR run-rate | C9: =Revenue!C15 -> 2763.9 | D9: =Revenue!D15 -> 4352.0166 | E9: =Revenue!E15 -> 12030.423 | F9: =Revenue!F15 -> 13752.13 | G9: =Revenue!G15 -> 15591.794 | H9: =Revenue!H15 -> 17564.636 | I9: =Revenue!I15 -> 19687.182 | J9: =Revenue!J15 -> 21977.404 | ... AL9: =Revenue!AL15 -> 325539.73
B10: Writer ARPU £/mo | C10: =IF(Funnel!C38=0,0,Revenue!C10/Funnel!C38) -> 12.336636 | D10: =IF(Funnel!D38=0,0,Revenue!D10/Funnel!D38) -> 13.594325 | E10: =IF(Funnel!E38=0,0,Revenue!E10/Funnel!E38) -> 14.322646 | F10: =IF(Funnel!F38=0,0,Revenue!F10/Funnel!F38) -> 14.807858 | G10: =IF(Funnel!G38=0,0,Revenue!G10/Funnel!G38) -> 15.160098 | H10: =IF(Funnel!H38=0,0,Revenue!H10/Funnel!H38) -> 15.430815 | I10: =IF(Funnel!I38=0,0,Revenue!I10/Funnel!I38) -> 15.647307 | J10: =IF(Funnel!J38=0,0,Revenue!J10/Funnel!J38) -> 15.825441 | ... AL10: =IF(Funnel!AL38=0,0,Revenue!AL10/Funnel!AL38) -> 17.020988
B11: New paying customers (subs + passes) | C11: =Funnel!C8+Funnel!C12 -> 10 | D11: =Funnel!D8+Funnel!D12 -> 11 | E11: =Funnel!E8+Funnel!E12 -> 12.1 | F11: =Funnel!F8+Funnel!F12 -> 13.31 | G11: =Funnel!G8+Funnel!G12 -> 14.641 | H11: =Funnel!H8+Funnel!H12 -> 16.1051 | I11: =Funnel!I8+Funnel!I12 -> 17.71561 | J11: =Funnel!J8+Funnel!J12 -> 19.487171 | ... AL11: =Funnel!AL8+Funnel!AL12 -> 281.02437
B12: CAC £ (marketing / new paying) | C12: =IF(C11=0,0,Assumptions!$B$55/C11) -> 150 | D12: =IF(D11=0,0,Assumptions!$B$55/D11) -> 136.36364 | E12: =IF(E11=0,0,Assumptions!$B$55/E11) -> 123.96694 | F12: =IF(F11=0,0,Assumptions!$B$55/F11) -> 112.69722 | G12: =IF(G11=0,0,Assumptions!$B$55/G11) -> 102.45202 | H12: =IF(H11=0,0,Assumptions!$B$55/H11) -> 93.138198 | I12: =IF(I11=0,0,Assumptions!$B$55/I11) -> 84.67109 | J12: =IF(J11=0,0,Assumptions!$B$55/J11) -> 76.973718 | ... AL12: =IF(AL11=0,0,Assumptions!$B$55/AL11) -> 5.3376154
B13: Blended writer churn %/mo | C13: =IF((Funnel!C14+Funnel!C19+Funnel!C24+Funnel!C29)=0,0,(Funnel!C16+Funnel!C21+Funnel!C26+Funnel!C30)/(Funnel!C14+Funnel!C19+Funnel!C24+Funnel!C29)) -> 0.03 | D13: =IF((Funnel!D14+Funnel!D19+Funnel!D24+Funnel!D29)=0,0,(Funnel!D16+Funnel!D21+Funnel!D26+Funnel!D30)/(Funnel!D14+Funnel!D19+Funnel!D24+Funnel!D29)) -> 0.042426352 | E13: =IF((Funnel!E14+Funnel!E19+Funnel!E24+Funnel!E29)=0,0,(Funnel!E16+Funnel!E21+Funnel!E26+Funnel!E30)/(Funnel!E14+Funnel!E19+Funnel!E24+Funnel!E29)) -> 0.047647566 | F13: =IF((Funnel!F14+Funnel!F19+Funnel!F24+Funnel!F29)=0,0,(Funnel!F16+Funnel!F21+Funnel!F26+Funnel!F30)/(Funnel!F14+Funnel!F19+Funnel!F24+Funnel!F29)) -> 0.050471652 | G13: =IF((Funnel!G14+Funnel!G19+Funnel!G24+Funnel!G29)=0,0,(Funnel!G16+Funnel!G21+Funnel!G26+Funnel!G30)/(Funnel!G14+Funnel!G19+Funnel!G24+Funnel!G29)) -> 0.052209904 | H13: =IF((Funnel!H14+Funnel!H19+Funnel!H24+Funnel!H29)=0,0,(Funnel!H16+Funnel!H21+Funnel!H26+Funnel!H30)/(Funnel!H14+Funnel!H19+Funnel!H24+Funnel!H29)) -> 0.053366676 | I13: =IF((Funnel!I14+Funnel!I19+Funnel!I24+Funnel!I29)=0,0,(Funnel!I16+Funnel!I21+Funnel!I26+Funnel!I30)/(Funnel!I14+Funnel!I19+Funnel!I24+Funnel!I29)) -> 0.054177318 | J13: =IF((Funnel!J14+Funnel!J19+Funnel!J24+Funnel!J29)=0,0,(Funnel!J16+Funnel!J21+Funnel!J26+Funnel!J30)/(Funnel!J14+Funnel!J19+Funnel!J24+Funnel!J29)) -> 0.054766396 | ... AL13: =IF((Funnel!AL14+Funnel!AL19+Funnel!AL24+Funnel!AL29)=0,0,(Funnel!AL16+Funnel!AL21+Funnel!AL26+Funnel!AL30)/(Funnel!AL14+Funnel!AL19+Funnel!AL24+Funnel!AL29)) -> 0.056828522
B14: LTV £ (ARPU × GM% / churn) | C14: =IF(C13=0,0,C10*COGS!C18/C13) -> 254.31361 | D14: =IF(D13=0,0,D10*COGS!D18/D13) -> 191.11472 | E14: =IF(E13=0,0,E10*COGS!E18/E13) -> 206.01345 | F14: =IF(F13=0,0,F10*COGS!F18/F13) -> 195.49126 | G14: =IF(G13=0,0,G10*COGS!G18/G13) -> 188.88921 | H14: =IF(H13=0,0,H10*COGS!H18/H13) -> 184.24849 | I14: =IF(I13=0,0,I10*COGS!I18/I13) -> 180.7683 | J14: =IF(J13=0,0,J10*COGS!J18/J13) -> 178.05045 | ... AL14: =IF(AL13=0,0,AL10*COGS!AL18/AL13) -> 163.42148
B15: LTV : CAC | C15: =IF(C12=0,0,C14/C12) -> 1.6954241 | D15: =IF(D12=0,0,D14/D12) -> 1.401508 | E15: =IF(E12=0,0,E14/E12) -> 1.6618418 | F15: =IF(F12=0,0,F14/F12) -> 1.7346591 | G15: =IF(G12=0,0,G14/G12) -> 1.8436846 | H15: =IF(H12=0,0,H14/H12) -> 1.9782269 | I15: =IF(I12=0,0,I14/I12) -> 2.1349471 | J15: =IF(J12=0,0,J14/J12) -> 2.3131331 | ... AL15: =IF(AL12=0,0,AL14/AL12) -> 30.616946
B16: Gross margin % | C16: =COGS!C18 -> 0.61843506 | D16: =COGS!D18 -> 0.59644744 | E16: =COGS!E18 -> 0.68535097 | F16: =COGS!F18 -> 0.66631966 | G16: =COGS!G18 -> 0.65051607 | H16: =COGS!H18 -> 0.63721387 | I16: =COGS!I18 -> 0.62589311 | J16: =COGS!J18 -> 0.61617123 | ... AL16: =COGS!AL18 -> 0.54562059
